<mujoco>
    <option timestep="0.001">
        <flag gravity="enable"/>
	</option>
    <worldbody>
        <light diffuse=".5 .5 .5" pos="0 0 3" dir="0 0 -1"/>
        <geom type="plane" pos="0 0 -0.1" size="1 1 0.1" rgba=".9 0 0 1"/>
        
        <site name="s1" pos="0.1 0 0" size="0.02"/>
        <site name="s2" pos="-0.1 0 0" size="0.02"/>
        
        <body pos="0 0 0.5" euler="0 0 0">
            <joint name="joint0" type="hinge" axis="0 -1 0" pos="0 0 -0.5" damping="0.001" limited="true" range="-90 90"/>
            <geom name="link0" type="cylinder" pos="0 0 0" size="0.05 .5" rgba="0 .9 0 1" mass="1"/>
             
            <site name="s3" pos="0.06 0 0.1" size="0.02"/>
            <site name="s4" pos="-0.06 0 0.1" size="0.02"/>
            
            <site name="s5" pos="0.06 0.05 -0.1" size="0.02"/>
            <site name="s6" pos="-0.06 0.05 -0.1" size="0.02"/>
             
            <body pos="0 0 0.5" euler="0 0 0">
                <joint name="joint1" type="hinge" axis="0 -1 0" pos="0 0 0" damping="0.001" limited="true" range="-90 90"/>
                <geom name="link1" type="box" pos="0 0 0" size="0.5 0.05 0.02" rgba="0 .9 0 1" mass="1"/>
                
                <site name="s7" pos="0.1 0.05 0" size="0.02"/>
                <site name="s8" pos="-0.1 0.05 0" size="0.02"/>
                
                <body pos="-0.5 0 0.1" euler="0 0 0">
                    <joint name="joint2" type="slide" axis="1 0 0" pos="0 0 0" damping="0" limited="true" range="0 1"/>
                    <geom name="link3" type="box" pos="0 0 0" size="0.05 0.05 0.05" rgba="0 .9 0 1" mass="1"/>
                </body>
            </body>
        </body>
    </worldbody>
    <tendon>
        <spatial name="joint0_r" width="0.01">
            <site site="s1"/>
            <site site="s3"/>
        </spatial>
        <spatial name="joint0_l" width="0.01">
            <site site="s2"/>
            <site site="s4"/>
        </spatial>
        <spatial name="joint1_r" width="0.01">
            <site site="s5"/>
            <site site="s7"/>
        </spatial>
        <spatial name="joint1_l" width="0.01">
            <site site="s6"/>
            <site site="s8"/>
        </spatial>
    </tendon>
    <actuator> 
        <muscle  name="muscle0_r" tendon="joint0_r" range="0.75 1.15" scale="400"/>
        <muscle  name="muscle0_l" tendon="joint0_l" range="0.75 1.15" scale="400"/>
        <muscle  name="muscle1_r" tendon="joint1_r" range="0.75 1.15" scale="400"/>
        <muscle  name="muscle1_l" tendon="joint1_l" range="0.75 1.15" scale="400"/>
    </actuator>
</mujoco>